Workbook

Sheet Raw Data
A1: Bank | B1: Year | C1: Net Income | D1: Total Assets | E1: Total Equity | F1: Loans | G1: Deposits | H1: Net Interest Income | I1: CET1 | J1: ROE | K1: ROA | L1: Net Yield | M1: Cost-to-Income | N1: Loan-to-Deposit | O1: LCR | P1: FX Rate
A2: JPMorgan Chase | B2: 2025 | C2: 57000 | D2: 4424900 | E2: 362438 | F2: 1493429 | G2: 2559320 | H2: 96443 | I2: 0.146 | J2: =C2/AVERAGE(E2,E3) -> 0.16120001 | K2: =C2/AVERAGE(D2,D3) -> 0.0135268 | L2: 0.022 | M2: 0.49 | N2: =F2/G2 -> 0.5835257 | O2: 1.11
A3: JPMorgan Chase | B3: 2024 | C3: 58471 | D3: 4002814 | E3: 344758 | F3: 1347988 | G3: 2406032 | H3: 92583 | I3: 0.157 | J3: =C3/AVERAGE(E3,E4) -> 0.17385629 | K3: =C3/AVERAGE(D3,D4) -> 0.014843733 | L3: 0.026 | M3: 0.5 | N3: =F3/G3 -> 0.56025356 | O3: 1.13
A4: JPMorgan Chase | B4: 2023 | C4: 49552 | D4: 3875393 | E4: 327878 | F4: 1323706 | G4: 2400688 | H4: 88267 | I4: 0.15 | J4: =C4/AVERAGE(E4,E5) -> 0.15979104 | K4: =C4/AVERAGE(D4,D5) -> 0.013141787 | L4: 0.028 | M4: 0.53 | N4: =F4/G4 -> 0.5513861 | O4: 1.13
A5: JPMorgan Chase | B5: 2022 | C5: 37676 | D5: 3665743 | E5: 292332 | F5: 1032282 | G5: 2340005 | H5: 66710 | I5: 0.132 | J5: =C5/AVERAGE(E5,E6) -> 0.1284877 | K5: =C5/AVERAGE(D5,D6) -> 0.010169908 | L5: 0.022 | M5: 0.59 | N5: =F5/G5 -> 0.44114521 | O5: 1.12
A6: JPMorgan Chase | B6: 2021 | C6: 48334 | D6: 3743567 | E6: 294121 | F6: 1077857 | G6: 2462292 | H6: 52311 | I6: 0.131 | J6: =C6/AVERAGE(E6,279354) -> 0.16856533 | K6: =C6/AVERAGE(D6,3386071) -> 0.013558613 | L6: 0.019 | M6: 0.59 | N6: =F6/G6 -> 0.4377454 | O6: 1.11
A7: Bank of America | B7: 2025 | C7: 30509 | D7: 3410394 | E7: 303243 | F7: 1185700 | G7: 2018729 | H7: 60096 | I7: 0.114 | J7: =C7/AVERAGE(E7,E8) -> 0.10217245 | K7: =C7/AVERAGE(D7,D8) -> 0.0091458045 | L7: 0.0201 | M7: 0.6275 | N7: =F7/G7 -> 0.58734976 | O7: 1.12
A8: Bank of America | B8: 2024 | C8: 26973 | D8: 3261299 | E8: 293963 | F8: 1095835 | G8: 1965467 | H8: 56060 | I8: 0.119 | J8: =C8/AVERAGE(E8,E9) -> 0.092119486 | K8: =C8/AVERAGE(D8,D9) -> 0.0083748224 | L8: 0.0195 | M8: 0.6304 | N8: =F8/G8 -> 0.55754434 | O8: 1.13
A9: Bank of America | B9: 2023 | C9: 26515 | D9: 3180151 | E9: 291646 | F9: 1053732 | G9: 1923827 | H9: 56931 | I9: 0.118 | J9: =C9/AVERAGE(E9,E10) -> 0.093884495 | K9: =C9/AVERAGE(D9,D10) -> 0.0085108678 | L9: 0.0208 | M9: 0.6641 | N9: =F9/G9 -> 0.547727 | O9: 1.15
A10: Bank of America | B10: 2022 | C10: 27528 | D10: 3050706 | E10: 273197 | F10: 1045747 | G10: 1930341 | H10: 51462 | I10: 0.112 | J10: =C10/AVERAGE(E10,E11) -> 0.10134318 | K10: =C10/AVERAGE(D10,D11) -> 0.0088505164 | L10: 0.0196 | M10: 0.6441 | N10: =F10/G10 -> 0.54174211 | O10: 1.2
A11: Bank of America | B11: 2021 | C11: 31978 | D11: 3169948 | E11: 270066 | F11: 979124 | G11: 2064446 | H11: 42934 | I11: 0.106 | J11: =C11/AVERAGE(E11,272924) -> 0.11778486 | K11: 0.0105 | L11: 0.0166 | M11: 0.6671 | N11: =F11/G11 -> 0.4742793 | O11: 1.15
A12: Wells Fargo | B12: 2025 | C12: 21338 | D12: 2148631 | E12: 183038 | F12: 986167 | G12: 1426207 | H12: 47484 | I12: 0.106 | J12: =C12/AVERAGE(E12,E13) -> 0.11720827 | K12: =C12/AVERAGE(D12,D13) -> 0.010463712 | L12: 0.0267 | M12: 0.66 | N12: =F12/G12 -> 0.69146134 | O12: 1.19
A13: Wells Fargo | B13: 2024 | C13: 19772 | D13: 1929845 | E13: 181066 | F13: 912745 | G13: 1371804 | H13: 47676 | I13: 0.1107 | J13: =C13/AVERAGE(E13,E14) -> 0.1073081 | K13: =C13/AVERAGE(D13,D14) -> 0.010238424 | L13: 0.0273 | M13: 0.66 | N13: =F13/G13 -> 0.66536109 | O13: 1.25
A14: Wells Fargo | B14: 2023 | C14: 19142 | D14: 1932468 | E14: 187443 | F14: 936682 | G14: 1358173 | H14: 52375 | I14: 0.1143 | J14: =C14/AVERAGE(E14,E15) -> 0.10390301 | K14: =C14/AVERAGE(D14,D15) -> 0.010039114 | L14: 0.0306 | M14: 0.67 | N14: =F14/G14 -> 0.68966325 | O14: 1.25
A15: Wells Fargo | B15: 2022 | C15: 13182 | D15: 1881016 | E15: 181016 | F15: 955871 | G15: 1383985 | H15: 44950 | I15: 0.106 | J15: =C15/AVERAGE(E15,E16) -> 0.071037869 | K15: =C15/AVERAGE(D15,D16) -> 0.0068851976 | L15: 0.0246 | M15: 0.77 | N15: =F15/G15 -> 0.69066572 | O15: 1.22
A16: Wells Fargo | B16: 2021 | C16: 21548 | D16: 1948068 | E16: 190110 | F16: 895394 | G16: 1482479 | H16: 35779 | I16: 0.1135 | J16: =C16/AVERAGE(E16,185712) -> 0.11467131 | K16: =C16/AVERAGE(D16,1952911) -> 0.011047483 | L16: 0.0203 | M16: 0.69 | N16: =F16/G16 -> 0.60398427 | O16: 1.18
A17: Citigroup | B17: 2025 | C17: 14306 | D17: 2657202 | E17: 212291 | F17: 752230 | G17: 1403573 | H17: 59792 | I17: 0.1318 | J17: =C17/AVERAGE(E17,E18) -> 0.067979919 | K17: =C17/AVERAGE(D17,D18) -> 0.0057108105 | L17: 0.0247 | M17: 0.647 | N17: =F17/G17 -> 0.53593935 | O17: 1.15
A18: Citigroup | B18: 2024 | C18: 12682 | D18: 2352945 | E18: 208598 | F18: 694488 | G18: 1284458 | H18: 54095 | I18: 0.1363 | J18: =C18/AVERAGE(E18,E19) -> 0.061258154 | K18: =C18/AVERAGE(D18,D19) -> 0.005323227 | L18: 0.024 | M18: 0.664 | N18: =F18/G18 -> 0.54068564 | O18: 1.16
A19: Citigroup | B19: 2023 | C19: 9228 | D19: 2411834 | E19: 205453 | F19: 689362 | G19: 1308681 | H19: 54900 | I19: 0.1337 | J19: =C19/AVERAGE(E19,E20) -> 0.04538636 | K19: =C19/AVERAGE(D19,D20) -> 0.0038222971 | L19: 0.0246 | M19: 0.717 | N19: =F19/G19 -> 0.52676091 | O19: 1.16
A20: Citigroup | B20: 2022 | C20: 14845 | D20: 2416676 | E20: 201189 | F20: 657221 | G20: 1365954 | H20: 48688 | I20: 0.1303 | J20: =C20/AVERAGE(E20,E21) -> 0.073643036 | K20: =C20/AVERAGE(D20,D21) -> 0.006306168 | L20: 0.0225 | M20: 0.679 | N20: =F20/G20 -> 0.48114431 | O20: 1.18
A21: Citigroup | B21: 2021 | C21: 21952 | D21: 2291413 | E21: 201972 | F21: 667767 | G21: 1317230 | H21: 42494 | I21: 0.1225 | J21: =C21/AVERAGE(E21,199442) -> 0.10937337 | K21: =C21/AVERAGE(D21,2260090) -> 0.0096460444 | L21: 0.0199 | M21: 0.669 | N21: =F21/G21 -> 0.50694791 | O21: 1.15
A22: Goldman Sachs | B22: 2025 | C22: 17176 | D22: 1809320 | E22: 124972 | F22: 239882 | G22: 501422 | H22: 13559 | I22: 0.15 | J22: =C22/AVERAGE(E22,E23) -> 0.13909494 | K22: =C22/AVERAGE(D22,D23) -> 0.009856276 | L22: - | M22: 0.644 | N22: =F22/G22 -> 0.47840342 | O22: 1.22
A23: Goldman Sachs | B23: 2024 | C23: 14276 | D23: 1675972 | E23: 121996 | F23: 200866 | G23: 433013 | H23: 8056 | I23: 0.15 | J23: =C23/AVERAGE(E23,E24) -> 0.11951394 | K23: =C23/AVERAGE(D23,D24) -> 0.0086063096 | L23: 0.0273 | M23: 0.631 | N23: =F23/G23 -> 0.46387984 | O23: 1.29
A24: Goldman Sachs | B24: 2023 | C24: 8516 | D24: 1641594 | E24: 116905 | F24: 183358 | G24: 428417 | H24: 6351 | I24: 0.144 | J24: =C24/AVERAGE(E24,E25) -> 0.072757098 | K24: =C24/AVERAGE(D24,D25) -> 0.005523785 | L24: 0.0225 | M24: 0.746 | N24: =F24/G24 -> 0.42798955 | O24: 1.28
A25: Goldman Sachs | B25: 2022 | C25: 11261 | D25: 1441799 | E25: 117189 | F25: 179286 | G25: 386665 | H25: 7678 | I25: 0.15 | J25: =C25/AVERAGE(E25,E26) -> 0.099165621 | K25: =C25/AVERAGE(D25,D26) -> 0.0077507402 | L25: 0.0246 | M25: 0.658 | N25: =F25/G25 -> 0.46367269 | O25: 1.26
A26: Goldman Sachs | B26: 2021 | C26: 21635 | D26: 1463988 | E26: 109926 | F26: 158562 | G26: 364227 | H26: 6470 | I26: 0.142 | J26: =C26/AVERAGE(E26,95932) -> 0.21019343 | K26: =C26/AVERAGE(D26,1163028) -> 0.01647116 | L26: 0.0199 | M26: 0.538 | N26: =F26/G26 -> 0.4353384 | O26: 1.23
A27: Morgan Stanley | B27: 2025 | C27: 17025 | D27: 1420270 | E27: 112652 | F27: 289038 | G27: 415523 | H27: 10046 | I27: 0.15 | J27: =C27/AVERAGE(E27,E28) -> 0.15613536 | K27: =C27/AVERAGE(D27,D28) -> 0.012920529 | L27: 0.025 | M27: 0.68 | N27: =F27/G27 -> 0.69560048 | O27: 1.34
A28: Morgan Stanley | B28: 2024 | C28: 13529 | D28: 1215071 | E28: 105428 | F28: 246814 | G28: 376007 | H28: 8611 | I28: 0.159 | J28: =C28/AVERAGE(E28,E29) -> 0.13172679 | K28: =C28/AVERAGE(D28,D29) -> 0.011233147 | L28: 0.026 | M28: 0.71 | N28: =F28/G28 -> 0.65640799 | O28: 1.3
A29: Morgan Stanley | B29: 2023 | C29: 9230 | D29: 1193693 | E29: 99982 | F29: - | G29: - | H29: 8230 | I29: 0.155 | J29: =C29/AVERAGE(E29,E30) -> 0.091743575 | K29: =C29/AVERAGE(D29,D30) -> 0.0077761546 | L29: 0.027 | M29: 0.77 | N29: - | O29: 1.29
A30: Morgan Stanley | B30: 2022 | C30: 11179 | D30: 1180231 | E30: 101231 | F30: - | G30: 356646 | H30: 9327 | I30: 0.153 | J30: =C30/AVERAGE(E30,E31) -> 0.10757883 | K30: =C30/AVERAGE(D30,D31) -> 0.0094402439 | L30: 0.026 | M30: 0.73 | N30: - | O30: 1.32
A31: Morgan Stanley | B31: 2021 | C31: 15120 | D31: 1188140 | E31: 106598 | F31: 200761 | G31: 647574 | H31: 8045 | I31: 0.16 | J31: =C31/AVERAGE(E31,1115862) -> 0.024737006 | K31: =C31/AVERAGE(D31,103149) -> 0.02341846 | L31: 0.024 | M31: 0.67 | N31: =F31/G31 -> 0.31002017 | O31: 1.34
A32: U.S. Bancorp | B32: 2025 | C32: 7596 | D32: 692345 | E32: 65651 | F32: 391335 | G32: 522216 | H32: 16649 | I32: 0.108 | J32: =C32/AVERAGE(E32,E33) -> 0.12183718 | K32: =C32/AVERAGE(D32,D33) -> 0.011083687 | L32: 0.0272 | M32: 0.586 | N32: =F32/G32 -> 0.74937382 | O32: 1.065
A33: U.S. Bancorp | B33: 2024 | C33: 6329 | D33: 678318 | E33: 59040 | F33: 379832 | G33: 218309 | H33: 16289 | I33: 0.016 | J33: =C33/AVERAGE(E33,E34) -> 0.11009254 | K33: =C33/AVERAGE(D33,D34) -> 0.0094335334 | L33: 0.027 | M33: 0.623 | N33: =F33/G33 -> 1.7398825 | O33: 1.066
A34: U.S. Bancorp | B34: 2023 | C34: 5458 | D34: 663491 | E34: 55936 | F34: 373835 | G34: 512312 | H34: 17396 | I34: 0.099 | J34: =C34/AVERAGE(E34,E35) -> 0.10219251 | K34: =C34/AVERAGE(D34,D35) -> 0.0086935746 | L34: 0.029 | M34: 0.667 | N34: =F34/G34 -> 0.72970182 | O34: 1.09
A35: U.S. Bancorp | B35: 2022 | C35: 5795 | D35: 592149 | E35: 50882 | F35: 387318 | G35: 511697 | H35: 14846 | I35: 0.093 | J35: =C35/AVERAGE(E35,E36) -> 0.1100414 | K35: =C35/AVERAGE(D35,D36) -> 0.01339214 | L35: 0.0272 | M35: 0.614 | N35: =F35/G35 -> 0.75692842 | O35: 1.11
A36: U.S. Bancorp | B36: 2021 | C36: 7963 | D36: 273284 | E36: 54442 | F36: 312028 | G36: 475399 | H36: 12600 | I36: 0.1 | J36: =C36/AVERAGE(E36,53095) -> 0.14809786 | K36: =C36/AVERAGE(D36,553905) -> 0.019253157 | L36: 0.0249 | M36: 0.604 | N36: =F36/G36 -> 0.65634972 | O36: 1.15
A37: PNC Financial Services Group | B37: 2025 | C37: 6997 | D37: 573572 | E37: 60585 | F37: 331481 | G37: 440866 | H37: 14410 | I37: 0.106 | J37: =C37/AVERAGE(E37,E38) -> 0.12167638 | K37: =C37/AVERAGE(D37,D38) -> 0.012344634 | L37: 0.0283 | M37: 0.6 | N37: =F37/G37 -> 0.75188606 | O37: 1.07
A38: PNC Financial Services Group | B38: 2024 | C38: 5953 | D38: 560038 | E38: 54425 | F38: 316467 | G38: 426738 | H38: 13499 | I38: 0.105 | J38: =C38/AVERAGE(E38,E39) -> 0.11278252 | K38: =C38/AVERAGE(D38,D39) -> 0.010615022 | L38: 0.0266 | M38: 0.63 | N38: =F38/G38 -> 0.74159555 | O38: 1.07
A39: PNC Financial Services Group | B39: 2023 | C39: 5647 | D39: 561580 | E39: 51141 | F39: 321508 | G39: 421418 | H39: 13916 | I39: 0.099 | J39: =C39/AVERAGE(E39,E40) -> 0.11648943 | K39: =C39/AVERAGE(D39,D40) -> 0.010090605 | L39: 0.0276 | M39: 0.65 | N39: =F39/G39 -> 0.76291948 | O39: 1.07
A40: PNC Financial Services Group | B40: 2022 | C40: 6097 | D40: 557679 | E40: 45812 | F40: 326025 | G40: 436282 | H40: 13014 | I40: 0.091 | J40: =C40/AVERAGE(E40,E41) -> 0.12009297 | K40: =C40/AVERAGE(D40,D41) -> 0.010936588 | L40: 0.0265 | M40: 0.62 | N40: =F40/G40 -> 0.74728043 | O40: 1.08
...

Sheet Ratio 
A1: Bank | B1: Avg ROE | C1: Avg ROA | D1: Avg Net Yield | E1: Avg CET1 | F1: Avg Cost-to-Income | G1: Avg LCR
A2: JPMorgan Chase | B2: =AVERAGE('Raw Data'!J2,'Raw Data'!J3,'Raw Data'!J4,'Raw Data'!J5,'Raw Data'!J7) -> 0.1451015 | C2: =AVERAGE('Raw Data'!K2:K6) -> 0.013048168 | D2: =AVERAGE('Raw Data'!L2:L6) -> 0.0234 | E2: =AVERAGE('Raw Data'!I2:I6) -> 0.1432 | F2: =AVERAGE('Raw Data'!M2:M6) -> 0.54 | G2: =AVERAGE('Raw Data'!O2:O6) -> 1.12
A3: Bank of America | B3: =AVERAGE('Raw Data'!J7:J11) -> 0.10146089 | C3: =AVERAGE('Raw Data'!K7:K11) -> 0.0090764022 | D3: =AVERAGE('Raw Data'!L7:L11) -> 0.01932 | E3: =AVERAGE('Raw Data'!I7:I11) -> 0.1138 | F3: =AVERAGE('Raw Data'!M7:M11) -> 0.64664 | G3: =AVERAGE('Raw Data'!O7:O11) -> 1.15
A4: Wells Fargo | B4: =AVERAGE('Raw Data'!J12:J16) -> 0.10282571 | C4: =AVERAGE('Raw Data'!K12:K16) -> 0.0097347863 | D4: =AVERAGE('Raw Data'!L12:L16) -> 0.0259 | E4: =AVERAGE('Raw Data'!I12:I16) -> 0.1101 | F4: =AVERAGE('Raw Data'!M12:M16) -> 0.69 | G4: =AVERAGE('Raw Data'!O12:O16) -> 1.218
A5: Citigroup | B5: =AVERAGE('Raw Data'!J17:J21) -> 0.071528167 | C5: =AVERAGE('Raw Data'!K17:K21) -> 0.0061617094 | D5: =AVERAGE('Raw Data'!L17:L21) -> 0.02314 | E5: =AVERAGE('Raw Data'!I17:I21) -> 0.13092 | F5: =AVERAGE('Raw Data'!M17:M21) -> 0.6752 | G5: =AVERAGE('Raw Data'!O17:O21) -> 1.16
A6: Goldman Sachs | B6: =AVERAGE('Raw Data'!J22:J26) -> 0.12814501 | C6: =AVERAGE('Raw Data'!K22:K26) -> 0.0096416541 | D6: =AVERAGE('Raw Data'!L22:L26) -> 0.023575 | E6: =AVERAGE('Raw Data'!I22:I26) -> 0.1472 | F6: =AVERAGE('Raw Data'!M22:M26) -> 0.6434 | G6: =AVERAGE('Raw Data'!O22:O26) -> 1.256
A7: Morgan Stanley | B7: =AVERAGE('Raw Data'!J27:J31) -> 0.10238431 | C7: =AVERAGE('Raw Data'!K27:K31) -> 0.012957707 | D7: =AVERAGE('Raw Data'!L27:L31) -> 0.0256 | E7: =AVERAGE('Raw Data'!I27:I31) -> 0.1554 | F7: =AVERAGE('Raw Data'!M27:M31) -> 0.712 | G7: =AVERAGE('Raw Data'!O27:O31) -> 1.318
A8: U.S. Bancorp | B8: =AVERAGE('Raw Data'!J32:J36) -> 0.1184523 | C8: =AVERAGE('Raw Data'!K32:K36) -> 0.012371219 | D8: =AVERAGE('Raw Data'!L32:L36) -> 0.02706 | E8: =AVERAGE('Raw Data'!J32:J36) -> 0.1184523 | F8: =AVERAGE('Raw Data'!M32:M36) -> 0.6188 | G8: =AVERAGE('Raw Data'!O32:O36) -> 1.0962
A9: PNC Financial Services Group | B9: =AVERAGE('Raw Data'!J37:J41) -> 0.1161092 | C9: =AVERAGE('Raw Data'!K37:K41) -> 0.011145088 | D9: =AVERAGE('Raw Data'!L37:L41) -> 0.02638 | E9: =AVERAGE('Raw Data'!I37:I41) -> 0.1008 | F9: =AVERAGE('Raw Data'!M37:M41) -> 0.636 | G9: =AVERAGE('Raw Data'!O37:O41) -> 1.078
A10: Truist Financial | B10: =AVERAGE('Raw Data'!J42:J46) -> 0.07233482 | C10: =AVERAGE('Raw Data'!K42:K46) -> 0.0087603741 | D10: =AVERAGE('Raw Data'!L42:L46) -> 0.02742 | E10: =AVERAGE('Raw Data'!I42:I46) -> 0.102 | F10: =AVERAGE('Raw Data'!M42:M46) -> 0.6852 | G10: =AVERAGE('Raw Data'!O42:O46) -> 1.116
A11: Capital One | B11: =AVERAGE('Raw Data'!J47:J51) -> 0.10510163 | C11: =AVERAGE('Raw Data'!K47:K51) -> 0.014021726 | D11: =AVERAGE('Raw Data'!L47:L51) -> 0.06846 | E11: =AVERAGE('Raw Data'!I47:I51) -> 0.1326 | F11: =AVERAGE('Raw Data'!M47:M51) -> 0.55526 | G11: =AVERAGE('Raw Data'!O47:O51) -> 1.592
A12: HSBC | B12: =AVERAGE('Raw Data'!J52:J56) -> 0.10625059 | C12: =AVERAGE('Raw Data'!K52:K56) -> 0.0068658212 | D12: =AVERAGE('Raw Data'!L52:L56) -> 0.01498 | E12: =AVERAGE('Raw Data'!I52:I56) -> 0.1492 | F12: =AVERAGE('Raw Data'!M52:M56) -> 0.5728 | G12: =AVERAGE('Raw Data'!O52:O56) -> 1.364
A13: Barclays PLC | B13: =AVERAGE('Raw Data'!J57:J61) -> 0.076964336 | C13: =AVERAGE('Raw Data'!K57:K61) -> 0.0037395015 | D13: =AVERAGE('Raw Data'!L57:L61) -> 0.0383 | E13: =AVERAGE('Raw Data'!I57:I61) -> 0.1374 | F13: =AVERAGE('Raw Data'!M57:M61) -> 0.64 | G13: =AVERAGE('Raw Data'!O57:O61) -> 1.6108
A14: Lloyds BG | B14: =AVERAGE('Raw Data'!J62:J66) -> 0.36353454 | C14: =AVERAGE('Raw Data'!K62:K66) -> 0.019428233 | D14: =SUM(AVERAGE('Raw Data'!L62:L66)) -> 0.0292 | E14: =AVERAGE('Raw Data'!I62:I66) -> 0.1504 | F14: =AVERAGE('Raw Data'!M62:M66) -> 0.5702 | G14: =AVERAGE('Raw Data'!O62:O66) -> 1.424
A15: BNP Paribas | B15: =AVERAGE('Raw Data'!J67:J71) -> 0.074890454 | C15: =AVERAGE('Raw Data'!K67:K71) -> 0.0041172977 | D15: =AVERAGE('Raw Data'!L67:L71) -> 0.00786 | E15: =AVERAGE('Raw Data'!I67:I71) -> 0.1278 | F15: =AVERAGE('Raw Data'!M67:M71) -> 0.6402 | G15: =AVERAGE('Raw Data'!O67:O71) -> 1.388
A16: Credit Agricole S.A. | B16: =AVERAGE('Raw Data'!J72:J76) -> 0.081579849 | C16: =AVERAGE('Raw Data'!K72:K76) -> 0.0030843479 | D16: =AVERAGE('Raw Data'!L72:L76) -> 0.00618 | E16: =AVERAGE('Raw Data'!I72:I76) -> 0.1168 | F16: =AVERAGE('Raw Data'!M72:M76) -> 0.563 | G16: =AVERAGE('Raw Data'!O72:O76) -> 1.46
A17: Deutsche Bank | B17: =AVERAGE('Raw Data'!J77:J81) -> 0.061692584 | C17: =AVERAGE('Raw Data'!K77:K81) -> 0.0029575107 | D17: =AVERAGE('Raw Data'!L77:L81) -> 0.00898 | E17: =AVERAGE('Raw Data'!I77:I81) -> 0.1366 | F17: =AVERAGE('Raw Data'!M77:M81) -> 0.7506 | G17: =AVERAGE('Raw Data'!O77:O81) -> 1.41
A18: Commerzbank | B18: =AVERAGE('Raw Data'!J82:J86) -> 0.064518993 | C18: =AVERAGE('Raw Data'!K82:K86) -> 0.0033782735 | D18: - | E18: =AVERAGE('Raw Data'!I82:I86) -> 0.146 | F18: =AVERAGE('Raw Data'!M82:M86) -> 0.6132 | G18: =AVERAGE('Raw Data'!O82:O86) -> 1.4706
A19: Santander Group | B19: =AVERAGE('Raw Data'!J87:J91) -> 0.10828386 | C19: =AVERAGE('Raw Data'!K87:K91) -> 0.0063614468 | D19: =AVERAGE('Raw Data'!L87:L91) -> 0.02356 | E19: =AVERAGE('Raw Data'!I87:I91) -> 0.1263 | F19: =AVERAGE('Raw Data'!M87:M91) -> 0.4382 | G19: =AVERAGE('Raw Data'!O87:O91) -> 1.608
A20: BBVA Group | B20: =AVERAGE('Raw Data'!J92:J96) -> 0.14443291 | C20: =AVERAGE('Raw Data'!K92:K96) -> 0.010530667 | D20: =AVERAGE('Raw Data'!L92:L96) -> 0.02834 | E20: =AVERAGE('Raw Data'!I92:I96) -> 0.12694 | F20: =AVERAGE('Raw Data'!M92:M96) -> 0.4178 | G20: =AVERAGE('Raw Data'!O92:O96) -> 1.5
A21: UniCredit | B21: =AVERAGE('Raw Data'!J97:J101) -> 0.11985846 | C21: =AVERAGE('Raw Data'!K97:K101) -> 0.0092210599 | D21: =AVERAGE('Raw Data'!L97:L101) -> 0.01488 | E21: =AVERAGE('Raw Data'!I97:I101) -> 0.15576 | F21: =AVERAGE('Raw Data'!M97:M101) -> 0.4354 | G21: =AVERAGE('Raw Data'!O97:O101) -> 1.568
A22: Intesa Sanpaolo | B22: =AVERAGE('Raw Data'!J102:J106) -> 0.10483435 | C22: =AVERAGE('Raw Data'!K102:K106) -> 0.0064837999 | D22: - | E22: =AVERAGE('Raw Data'!I102:I106) -> 0.1364 | F22: =AVERAGE('Raw Data'!M102:M106) -> 0.479 | G22: =AVERAGE('Raw Data'!O102:O106) -> 1.752
A23: UBS Group | B23: =AVERAGE('Raw Data'!J107:J111) -> 0.15747334 | C23: =AVERAGE('Raw Data'!K107:K111) -> 0.0082480656 | D23: =AVERAGE('Raw Data'!L107:L111) -> 0.00516 | E23: =AVERAGE('Raw Data'!I107:I111) -> 0.1444 | F23: =AVERAGE('Raw Data'!M107:M111) -> 0.8132 | G23: =AVERAGE('Raw Data'!O107:O111) -> 1.8092
A24: Commonwealth Bank Australia | B24: =AVERAGE('Raw Data'!J112:J115) -> 0.1342248 | C24: =AVERAGE('Raw Data'!K112:K116) -> 0.0079882314 | D24: =AVERAGE('Raw Data'!L112:L116) -> 0.01742 | E24: =AVERAGE('Raw Data'!I112:I116) -> 0.1228 | F24: =AVERAGE('Raw Data'!M112:M116) -> 0.4542 | G24: =AVERAGE('Raw Data'!O112:O116) -> 1.312
A25: Mitsubishi UFJ Financial Group | B25: =AVERAGE('Raw Data'!J117:J121) -> 0.048286953 | C25: =AVERAGE('Raw Data'!K117:K121) -> 0.002213808 | D25: =AVERAGE('Raw Data'!L117:L121) -> 0.0044 | E25: =AVERAGE('Raw Data'!I117:I121) -> 0.1232 | F25: =AVERAGE('Raw Data'!M117:M121) -> 0.578 | G25: =AVERAGE('Raw Data'!O117:O121) -> 1.512
A26: Sumitomo Mitsui Financial Group | B26: =AVERAGE('Raw Data'!J122:J126) -> 0.050207476 | C26: =AVERAGE('Raw Data'!K122:K126) -> 0.0026815818 | D26: =AVERAGE('Raw Data'!L122:L126) -> 0.00672 | E26: =AVERAGE('Raw Data'!I122:I126) -> 0.13964 | F26: =AVERAGE('Raw Data'!M122:M126) -> 0.5572 | G26: =AVERAGE('Raw Data'!O122:O126) -> 1.362
A27: Industrial and Commercial Bank of China | B27: =AVERAGE('Raw Data'!J127:J131) -> 0.097897957 | C27: =AVERAGE('Raw Data'!K127:K131) -> 0.0085306517 | D27: =AVERAGE('Raw Data'!L127:L131) -> 0.0151 | E27: =AVERAGE('Raw Data'!I127:I131) -> 0.13748 | F27: =AVERAGE('Raw Data'!M127:M131) -> 0.28154 | G27: =AVERAGE('Raw Data'!O127:O131) -> 1.262
A28: China Construction Bank | B28: =AVERAGE('Raw Data'!J132:J135) -> 0.10554066 | C28: =AVERAGE('Raw Data'!K132:K136) -> 0.0090088645 | D28: =AVERAGE('Raw Data'!L132:L136) -> 0.016025 | E28: =AVERAGE('Raw Data'!I132:I136) -> 0.13908 | F28: =AVERAGE('Raw Data'!M132:M136) -> 0.28602 | G28: =AVERAGE('Raw Data'!O132:O136) -> 1.264
A29: DBS Group Holdings | B29: =AVERAGE('Raw Data'!J137:J141) -> 0.1508935 | C29: =AVERAGE('Raw Data'!K137:K141) -> 0.012299834 | D29: =AVERAGE('Raw Data'!L137:L141) -> 0.01444 | E29: =AVERAGE('Raw Data'!I137:I141) -> 0.1552 | F29: =AVERAGE('Raw Data'!M138:M142) -> 0.4222 | G29: =AVERAGE('Raw Data'!O137:O141) -> 1.442
A30: United Overseas Bank | B30: =AVERAGE('Raw Data'!J142:J146) -> 0.11292589 | C30: =AVERAGE('Raw Data'!K142:K146) -> 0.010185407 | D30: =AVERAGE('Raw Data'!L142:L146) -> 0.01676 | E30: =AVERAGE('Raw Data'!I142:I146) -> 0.1416 | F30: =AVERAGE('Raw Data'!M142:M146) -> 0.446 | G30: =AVERAGE('Raw Data'!O142:O146) -> 1.42
A31: Maybank | B31: =AVERAGE('Raw Data'!J147:J151) -> 0.10264507 | C31: =SUM(AVERAGE('Raw Data'!K147:K151)) -> 0.0094272943 | D31: =AVERAGE('Raw Data'!L147:L151) -> 0.0676 | E31: =AVERAGE('Raw Data'!I147:I151) -> 0.15952 | F31: =AVERAGE('Raw Data'!M147:M151) -> 0.4742 | G31: =AVERAGE('Raw Data'!O147:O151) -> 1.3733333

Sheet Dashboard
A1: Bank Financial Analysis Dashboard
A3: Top 5 Banks
A4: 1. Lloyds BG
A5: 2.BBVA Group
A6: 3.DBS Group Holdings
A7: 4.Capital One
A8: 5.UniCredit
